<?xml version="1.0" encoding="utf-8"?>
<!-- This URDF was automatically created by SolidWorks to URDF Exporter! Originally created by Stephen Brawner (brawner@gmail.com) 
     Commit Version: 1.5.1-0-g916b5db  Build Version: 1.5.7152.31018
     For more information, please see http://wiki.ros.org/sw_urdf_exporter -->
<robot
  name="h_frame_tilt">
  <link
    name="base_link">
    <inertial>
      <origin
        xyz="-0.0095798 5.0778E-17 3.8835E-06"
        rpy="0 0 0" />
      <mass
        value="1.3164" />
      <inertia
        ixx="0.11389"
        ixy="1.6795E-18"
        ixz="1.0583E-05"
        iyy="0.062911"
        iyz="-9.8157E-19"
        izz="0.17671" />
    </inertial>
    <visual>
      <origin
        xyz="0 0 0"
        rpy="0 0 0" />
      <geometry>
        <mesh
          filename="package://h_frame_tilt/meshes/base_link.STL" />
      </geometry>
      <material
        name="">
        <color
          rgba="1 1 1 1" />
      </material>
    </visual>
    <collision>
      <origin
        xyz="0 0 0"
        rpy="0 0 0" />
      <geometry>
        <mesh
          filename="package://h_frame_tilt/meshes/base_link.STL" />
      </geometry>
    </collision>
  </link>
  <link
    name="motor_0">
    <inertial>
      <origin
        xyz="-2.8981E-09 -0.025 0.0040884"
        rpy="0 0 0" />
      <mass
        value="0.0010357" />
      <inertia
        ixx="8.5769E-08"
        ixy="-3.0484E-15"
        ixz="-2.6264E-14"
        iyy="5.524E-08"
        iyz="-9.7823E-14"
        izz="7.6225E-08" />
    </inertial>
    <visual>
      <origin
        xyz="0 0 0"
        rpy="0 0 0" />
      <geometry>
        <mesh
          filename="package://h_frame_tilt/meshes/motor_0.STL" />
      </geometry>
      <material
        name="">
        <color
          rgba="1 1 1 1" />
      </material>
    </visual>
    <collision>
      <origin
        xyz="0 0 0"
        rpy="0 0 0" />
      <geometry>
        <mesh
          filename="package://h_frame_tilt/meshes/motor_0.STL" />
      </geometry>
    </collision>
  </link>
  <joint
    name="motor_0_joint"
    type="fixed">
    <origin
      xyz="0.43 -0.3 0.005"
      rpy="0 0 0" />
    <parent
      link="base_link" />
    <child
      link="motor_0" />
    <axis
      xyz="0 0 0" />
    <limit
      lower="1.5708"
      upper="-0.34907"
      effort="0"
      velocity="0" />
  </joint>
  <link
    name="rotor_0">
    <inertial>
      <origin
        xyz="4.4346E-09 3.4328E-08 -0.00744"
        rpy="0 0 0" />
      <mass
        value="0.067291" />
      <inertia
        ixx="0.0014412"
        ixy="-7.5965E-05"
        ixz="-8.781E-13"
        iyy="1.2633E-05"
        iyz="-3.4466E-12"
        izz="0.0014525" />
    </inertial>
    <visual>
      <origin
        xyz="0 0 0"
        rpy="0 0 0" />
      <geometry>
        <mesh
          filename="package://h_frame_tilt/meshes/rotor_0.STL" />
      </geometry>
      <material
        name="">
        <color
          rgba="1 1 1 1" />
      </material>
    </visual>
    <collision>
      <origin
        xyz="0 0 0"
        rpy="0 0 0" />
      <geometry>
        <mesh
          filename="package://h_frame_tilt/meshes/rotor_0.STL" />
      </geometry>
    </collision>
  </link>
  <joint
    name="rotor_0_joint"
    type="continuous">
    <origin
      xyz="0 -0.025 0.021"
      rpy="0 0 0" />
    <parent
      link="motor_0" />
    <child
      link="rotor_0" />
    <axis
      xyz="0 0 1" />
  </joint>
  <link
    name="motor_2">
    <inertial>
      <origin
        xyz="-2.8981E-09 0.025 0.0040884"
        rpy="0 0 0" />
      <mass
        value="0.0010357" />
      <inertia
        ixx="8.5769E-08"
        ixy="-3.0484E-15"
        ixz="-2.6264E-14"
        iyy="5.524E-08"
        iyz="-9.7823E-14"
        izz="7.6225E-08" />
    </inertial>
    <visual>
      <origin
        xyz="0 0 0"
        rpy="0 0 0" />
      <geometry>
        <mesh
          filename="package://h_frame_tilt/meshes/motor_2.STL" />
      </geometry>
      <material
        name="">
        <color
          rgba="1 1 1 1" />
      </material>
    </visual>
    <collision>
      <origin
        xyz="0 0 0"
        rpy="0 0 0" />
      <geometry>
        <mesh
          filename="package://h_frame_tilt/meshes/motor_2.STL" />
      </geometry>
    </collision>
  </link>
  <joint
    name="motor_2_joint"
    type="fixed">
    <origin
      xyz="0.43 0.3 0.005"
      rpy="0 0 0" />
    <parent
      link="base_link" />
    <child
      link="motor_2" />
    <axis
      xyz="0 0 0" />
    <limit
      lower="1.5708"
      upper="-0.34907"
      effort="0"
      velocity="0" />
  </joint>
  <link
    name="rotor_2">
    <inertial>
      <origin
        xyz="7.0019E-09 6.3072E-09 -0.00744"
        rpy="0 0 0" />
      <mass
        value="0.067292" />
      <inertia
        ixx="0.0014451"
        ixy="-1.3765E-05"
        ixz="-1.154E-12"
        iyy="8.7366E-06"
        iyz="-9.362E-13"
        izz="0.0014525" />
    </inertial>
    <visual>
      <origin
        xyz="0 0 0"
        rpy="0 0 0" />
      <geometry>
        <mesh
          filename="package://h_frame_tilt/meshes/rotor_2.STL" />
      </geometry>
      <material
        name="">
        <color
          rgba="1 1 1 1" />
      </material>
    </visual>
    <collision>
      <origin
        xyz="0 0 0"
        rpy="0 0 0" />
      <geometry>
        <mesh
          filename="package://h_frame_tilt/meshes/rotor_2.STL" />
      </geometry>
    </collision>
  </link>
  <joint
    name="rotor_2_joint"
    type="continuous">
    <origin
      xyz="0 0.025 0.021"
      rpy="0 0 0" />
    <parent
      link="motor_2" />
    <child
      link="rotor_2" />
    <axis
      xyz="0 0 1" />
  </joint>
  <link
    name="rotor_3">
    <inertial>
      <origin
        xyz="7.0427E-09 -7.0503E-09 0.015147"
        rpy="0 0 0" />
      <mass
        value="0.067296" />
      <inertia
        ixx="0.0014418"
        ixy="-7.2037E-05"
        ixz="-1.1454E-12"
        iyy="1.2226E-05"
        iyz="1.0716E-12"
        izz="0.0014526" />
    </inertial>
    <visual>
      <origin
        xyz="0 0 0"
        rpy="0 0 0" />
      <geometry>
        <mesh
          filename="package://h_frame_tilt/meshes/rotor_3.STL" />
      </geometry>
      <material
        name="">
        <color
          rgba="1 1 1 1" />
      </material>
    </visual>
    <collision>
      <origin
        xyz="0 0 0"
        rpy="0 0 0" />
      <geometry>
        <mesh
          filename="package://h_frame_tilt/meshes/rotor_3.STL" />
      </geometry>
    </collision>
  </link>
  <joint
    name="rotor_3_joint"
    type="continuous">
    <origin
      xyz="-0.43 -0.325 0.0034134"
      rpy="0 0 0" />
    <parent
      link="base_link" />
    <child
      link="rotor_3" />
    <axis
      xyz="0 0 1" />
  </joint>
  <link
    name="rotor_1">
    <inertial>
      <origin
        xyz="-1.225E-08 2.2262E-08 0.015147"
        rpy="0 0 0" />
      <mass
        value="0.067291" />
      <inertia
        ixx="0.0014428"
        ixy="5.9289E-05"
        ixz="1.6714E-12"
        iyy="1.1056E-05"
        iyz="-1.5765E-12"
        izz="0.0014525" />
    </inertial>
    <visual>
      <origin
        xyz="0 0 0"
        rpy="0 0 0" />
      <geometry>
        <mesh
          filename="package://h_frame_tilt/meshes/rotor_1.STL" />
      </geometry>
      <material
        name="">
        <color
          rgba="1 1 1 1" />
      </material>
    </visual>
    <collision>
      <origin
        xyz="0 0 0"
        rpy="0 0 0" />
      <geometry>
        <mesh
          filename="package://h_frame_tilt/meshes/rotor_1.STL" />
      </geometry>
    </collision>
  </link>
  <joint
    name="rotor_1_joint"
    type="continuous">
    <origin
      xyz="-0.43 0.325 0.0034134"
      rpy="0 0 0" />
    <parent
      link="base_link" />
    <child
      link="rotor_1" />
    <axis
      xyz="0 0 1" />
  </joint>
</robot>