<?xml version="1.0" encoding="utf-8"?>
<!-- This URDF was automatically created by SolidWorks to URDF Exporter! Originally created by Stephen Brawner (brawner@gmail.com) 
     Commit Version: 1.5.1-0-g916b5db  Build Version: 1.5.7152.31018
     For more information, please see http://wiki.ros.org/sw_urdf_exporter -->
<robot
  name="h_frame_2">
  <link
    name="base_link">
    <inertial>
      <origin
        xyz="1.0362E-16 -1.4325E-17 2.1964E-05"
        rpy="0 0 0" />
      <mass
        value="1.3457" />
      <inertia
        ixx="0.11698"
        ixy="1.7047E-19"
        ixz="2.9273E-18"
        iyy="0.068468"
        iyz="4.8359E-19"
        izz="0.18536" />
    </inertial>
    <visual>
      <origin
        xyz="0 0 0"
        rpy="0 0 0" />
      <geometry>
        <mesh
          filename="package://h_frame_2/meshes/base_link.STL" />
      </geometry>
      <material
        name="">
        <color
          rgba="1 1 1 1" />
      </material>
    </visual>
    <collision>
      <origin
        xyz="0 0 0"
        rpy="0 0 0" />
      <geometry>
        <mesh
          filename="package://h_frame_2/meshes/base_link.STL" />
      </geometry>
    </collision>
  </link>
  <link
    name="rotor_0">
    <inertial>
      <origin
        xyz="7.2195E-09 5.5547E-09 0.015147"
        rpy="0 0 0" />
      <mass
        value="0.067291" />
      <inertia
        ixx="0.0014425"
        ixy="-6.2329E-05"
        ixz="-1.1867E-12"
        iyy="1.1314E-05"
        iyz="-8.6607E-13"
        izz="0.0014525" />
    </inertial>
    <visual>
      <origin
        xyz="0 0 0"
        rpy="0 0 0" />
      <geometry>
        <mesh
          filename="package://h_frame_2/meshes/rotor_0.STL" />
      </geometry>
      <material
        name="">
        <color
          rgba="1 1 1 1" />
      </material>
    </visual>
    <collision>
      <origin
        xyz="0 0 0"
        rpy="0 0 0" />
      <geometry>
        <mesh
          filename="package://h_frame_2/meshes/rotor_0.STL" />
      </geometry>
    </collision>
  </link>
  <joint
    name="rotor_0_joint"
    type="continuous">
    <origin
      xyz="0.43 -0.325 0.0034134"
      rpy="0 0 -0.022582" />
    <parent
      link="base_link" />
    <child
      link="rotor_0" />
    <axis
      xyz="0 0 1" />
  </joint>
  <link
    name="rotor_1">
    <inertial>
      <origin
        xyz="-7.205E-09 -6.1367E-09 0.015147"
        rpy="0 0 0" />
      <mass
        value="0.067291" />
      <inertia
        ixx="0.0014425"
        ixy="-6.2329E-05"
        ixz="1.1866E-12"
        iyy="1.1314E-05"
        iyz="9.1224E-13"
        izz="0.0014525" />
    </inertial>
    <visual>
      <origin
        xyz="0 0 0"
        rpy="0 0 0" />
      <geometry>
        <mesh
          filename="package://h_frame_2/meshes/rotor_1.STL" />
      </geometry>
      <material
        name="">
        <color
          rgba="1 1 1 1" />
      </material>
    </visual>
    <collision>
      <origin
        xyz="0 0 0"
        rpy="0 0 0" />
      <geometry>
        <mesh
          filename="package://h_frame_2/meshes/rotor_1.STL" />
      </geometry>
    </collision>
  </link>
  <joint
    name="rotor_1_joint"
    type="continuous">
    <origin
      xyz="-0.43 0.325 0.0034134"
      rpy="0 0 0.040814" />
    <parent
      link="base_link" />
    <child
      link="rotor_1" />
    <axis
      xyz="0 0 1" />
  </joint>
  <link
    name="rotor_2">
    <inertial>
      <origin
        xyz="-7.7019E-09 5.375E-09 0.015147"
        rpy="0 0 0" />
      <mass
        value="0.067296" />
      <inertia
        ixx="0.0014427"
        ixy="6.2333E-05"
        ixz="1.2405E-12"
        iyy="1.1315E-05"
        iyz="-8.5659E-13"
        izz="0.0014526" />
    </inertial>
    <visual>
      <origin
        xyz="0 0 0"
        rpy="0 0 0" />
      <geometry>
        <mesh
          filename="package://h_frame_2/meshes/rotor_2.STL" />
      </geometry>
      <material
        name="">
        <color
          rgba="1 1 1 1" />
      </material>
    </visual>
    <collision>
      <origin
        xyz="0 0 0"
        rpy="0 0 0" />
      <geometry>
        <mesh
          filename="package://h_frame_2/meshes/rotor_2.STL" />
      </geometry>
    </collision>
  </link>
  <joint
    name="rotor_2_joint"
    type="continuous">
    <origin
      xyz="0.43 0.325 0.0034134"
      rpy="0 0 -0.026759" />
    <parent
      link="base_link" />
    <child
      link="rotor_2" />
    <axis
      xyz="0 0 1" />
  </joint>
  <link
    name="rotor_3">
    <inertial>
      <origin
        xyz="-7.6402E-09 7.7923E-09 0.015147"
        rpy="0 0 0" />
      <mass
        value="0.067296" />
      <inertia
        ixx="0.0014427"
        ixy="6.2333E-05"
        ixz="1.2373E-12"
        iyy="1.1315E-05"
        iyz="-1.0807E-12"
        izz="0.0014526" />
    </inertial>
    <visual>
      <origin
        xyz="0 0 0"
        rpy="0 0 0" />
      <geometry>
        <mesh
          filename="package://h_frame_2/meshes/rotor_3.STL" />
      </geometry>
      <material
        name="">
        <color
          rgba="1 1 1 1" />
      </material>
    </visual>
    <collision>
      <origin
        xyz="0 0 0"
        rpy="0 0 0" />
      <geometry>
        <mesh
          filename="package://h_frame_2/meshes/rotor_3.STL" />
      </geometry>
    </collision>
  </link>
  <joint
    name="rotor_3_joint"
    type="continuous">
    <origin
      xyz="-0.43 -0.325 0.0034134"
      rpy="0 0 -0.0035185" />
    <parent
      link="base_link" />
    <child
      link="rotor_3" />
    <axis
      xyz="0 0 1" />
  </joint>
</robot>