<?xml version="1.0" encoding="utf-8"?>
<!-- This URDF was automatically created by SolidWorks to URDF Exporter! Originally created by Stephen Brawner (brawner@gmail.com) 
     Commit Version: 1.5.1-0-g916b5db  Build Version: 1.5.7152.31018
     For more information, please see http://wiki.ros.org/sw_urdf_exporter -->
<robot
  name="vtol_gauthali_11">
  <link
    name="base_link">
    <inertial>
      <origin
        xyz="-0.119905079244827 8.39675143464668E-06 -0.0550054700607095"
        rpy="0 0 0" />
      <mass
        value="9.00567659004051" />
      <inertia
        ixx="0.32386721070559"
        ixy="7.81346457012257E-06"
        ixz="0.0128409614131834"
        iyy="0.240986458514625"
        iyz="-1.50384477424153E-06"
        izz="0.516376617454283" />
    </inertial>
    <visual>
      <origin
        xyz="0 0 0"
        rpy="0 0 0" />
      <geometry>
        <mesh
          filename="package://vtol_gauthali_11/meshes/base_link.STL" />
      </geometry>
      <material
        name="">
        <color
          rgba="0.698039215686274 0.698039215686274 0.698039215686274 1" />
      </material>
    </visual>
    <collision>
      <origin
        xyz="0 0 0"
        rpy="0 0 0" />
      <geometry>
        <mesh
          filename="package://vtol_gauthali_11/meshes/base_link.STL" />
      </geometry>
    </collision>
  </link>
  <link
    name="left_ruddervator">
    <inertial>
      <origin
        xyz="0.029088 -0.0071511 0.0084768"
        rpy="0 0 0" />
      <mass
        value="0.011825" />
      <inertia
        ixx="0.0002244"
        ixy="3.7585E-10"
        ixz="-1.8506E-06"
        iyy="0.00022971"
        iyz="-5.9334E-09"
        izz="5.7467E-06" />
    </inertial>
    <visual>
      <origin
        xyz="0 0 0"
        rpy="0 0 0" />
      <geometry>
        <mesh
          filename="package://vtol_gauthali_11/meshes/left_ruddervator.STL" />
      </geometry>
      <material
        name="">
        <color
          rgba="0.98824 0.73725 0.51765 1" />
      </material>
    </visual>
    <collision>
      <origin
        xyz="0 0 0"
        rpy="0 0 0" />
      <geometry>
        <mesh
          filename="package://vtol_gauthali_11/meshes/left_ruddervator.STL" />
      </geometry>
    </collision>
  </link>
  <joint
    name="left_ruddervator_joint"
    type="revolute">
    <origin
      xyz="-1.3278 0.17783 0.17783"
      rpy="2.3562 0 3.1416" />
    <parent
      link="base_link" />
    <child
      link="left_ruddervator" />
    <axis
      xyz="0 0 1" />
    <limit
      lower="-0.53"
      upper="0.53"
      effort="-1"
      velocity="-1" />
  </joint>
  <link
    name="left_aileron">
    <inertial>
      <origin
        xyz="-0.019251 0.45424 -0.00070842"
        rpy="0 0 0" />
      <mass
        value="0.0090384" />
      <inertia
        ixx="0.0006329"
        ixy="3.2735E-07"
        ixz="2.5966E-07"
        iyy="1.7477E-06"
        iyz="3.2316E-07"
        izz="0.00063444" />
    </inertial>
    <visual>
      <origin
        xyz="0 0 0"
        rpy="0 0 0" />
      <geometry>
        <mesh
          filename="package://vtol_gauthali_11/meshes/left_aileron.STL" />
      </geometry>
      <material
        name="">
        <color
          rgba="0.69804 0.69804 0.69804 1" />
      </material>
    </visual>
    <collision>
      <origin
        xyz="0 0 0"
        rpy="0 0 0" />
      <geometry>
        <mesh
          filename="package://vtol_gauthali_11/meshes/left_aileron.STL" />
      </geometry>
    </collision>
  </link>
  <joint
    name="left_aileron_joint"
    type="revolute">
    <origin
      xyz="-0.28599 0.38 0.006356"
      rpy="0 0 0" />
    <parent
      link="base_link" />
    <child
      link="left_aileron" />
    <axis
      xyz="0 1 0" />
    <limit
      lower="-0.53"
      upper="0.53"
      effort="-1"
      velocity="-1" />
  </joint>
  <link
    name="right_aileron">
    <inertial>
      <origin
        xyz="-0.019048 -0.45424 0.0028768"
        rpy="0 0 0" />
      <mass
        value="0.0090385" />
      <inertia
        ixx="0.00063306"
        ixy="-3.8157E-07"
        ixz="5.2128E-07"
        iyy="1.7477E-06"
        iyz="-2.5684E-07"
        izz="0.00063429" />
    </inertial>
    <visual>
      <origin
        xyz="0 0 0"
        rpy="0 0 0" />
      <geometry>
        <mesh
          filename="package://vtol_gauthali_11/meshes/right_aileron.STL" />
      </geometry>
      <material
        name="">
        <color
          rgba="0.69804 0.69804 0.69804 1" />
      </material>
    </visual>
    <collision>
      <origin
        xyz="0 0 0"
        rpy="0 0 0" />
      <geometry>
        <mesh
          filename="package://vtol_gauthali_11/meshes/right_aileron.STL" />
      </geometry>
    </collision>
  </link>
  <joint
    name="right_aileron_joint"
    type="revolute">
    <origin
      xyz="-0.28599 -0.38 0.006356"
      rpy="0 0 0" />
    <parent
      link="base_link" />
    <child
      link="right_aileron" />
    <axis
      xyz="0 1 0" />
    <limit
      lower="-0.53"
      upper="0.53"
      effort="1"
      velocity="1" />
  </joint>
  <link
    name="rotor_0">
    <inertial>
      <origin
        xyz="0.007 -1.2546E-07 0.015147"
        rpy="0 0 0" />
      <mass
        value="0.067297" />
      <inertia
        ixx="0.0014438"
        ixy="-4.626E-05"
        ixz="-2.2886E-12"
        iyy="1.0096E-05"
        iyz="1.3106E-11"
        izz="0.0014525" />
    </inertial>
    <visual>
      <origin
        xyz="0 0 0"
        rpy="0 0 0" />
      <geometry>
        <mesh
          filename="package://vtol_gauthali_11/meshes/rotor_0.STL" />
      </geometry>
      <material
        name="">
        <color
          rgba="1 1 1 1" />
      </material>
    </visual>
    <collision>
      <origin
        xyz="0 0 0"
        rpy="0 0 0" />
      <geometry>
        <mesh
          filename="package://vtol_gauthali_11/meshes/rotor_0.STL" />
      </geometry>
    </collision>
  </link>
  <joint
    name="rotor_0_joint"
    type="continuous">
    <origin
      xyz="0.564 -0.35355 0.0064134"
      rpy="0 0 0" />
    <parent
      link="base_link" />
    <child
      link="rotor_0" />
    <axis
      xyz="0 0 1" />
  </joint>
  <link
    name="rotor_1">
    <inertial>
      <origin
        xyz="0.007 1.2587E-07 0.015147"
        rpy="0 0 0" />
      <mass
        value="0.067297" />
      <inertia
        ixx="0.0014429"
        ixy="-5.8288E-05"
        ixz="2.1818E-12"
        iyy="1.0974E-05"
        iyz="-1.307E-11"
        izz="0.0014525" />
    </inertial>
    <visual>
      <origin
        xyz="0 0 0"
        rpy="0 0 0" />
      <geometry>
        <mesh
          filename="package://vtol_gauthali_11/meshes/rotor_1.STL" />
      </geometry>
      <material
        name="">
        <color
          rgba="1 1 1 1" />
      </material>
    </visual>
    <collision>
      <origin
        xyz="0 0 0"
        rpy="0 0 0" />
      <geometry>
        <mesh
          filename="package://vtol_gauthali_11/meshes/rotor_1.STL" />
      </geometry>
    </collision>
  </link>
  <joint
    name="rotor_1_joint"
    type="continuous">
    <origin
      xyz="-0.836 0.35355 0.0064134"
      rpy="0 0 0" />
    <parent
      link="base_link" />
    <child
      link="rotor_1" />
    <axis
      xyz="0 0 1" />
  </joint>
  <link
    name="rotor_2">
    <inertial>
      <origin
        xyz="0.007 -8.4088E-08 0.015147"
        rpy="0 0 0" />
      <mass
        value="0.067299" />
      <inertia
        ixx="0.001442"
        ixy="-6.9181E-05"
        ixz="1.0898E-12"
        iyy="1.1945E-05"
        iyz="9.2792E-12"
        izz="0.0014526" />
    </inertial>
    <visual>
      <origin
        xyz="0 0 0"
        rpy="0 0 0" />
      <geometry>
        <mesh
          filename="package://vtol_gauthali_11/meshes/rotor_2.STL" />
      </geometry>
      <material
        name="">
        <color
          rgba="1 1 1 1" />
      </material>
    </visual>
    <collision>
      <origin
        xyz="0 0 0"
        rpy="0 0 0" />
      <geometry>
        <mesh
          filename="package://vtol_gauthali_11/meshes/rotor_2.STL" />
      </geometry>
    </collision>
  </link>
  <joint
    name="rotor_2_joint"
    type="continuous">
    <origin
      xyz="0.564 0.35355 0.0064134"
      rpy="0 0 0" />
    <parent
      link="base_link" />
    <child
      link="rotor_2" />
    <axis
      xyz="0 0 1" />
  </joint>
  <link
    name="rotor_3">
    <inertial>
      <origin
        xyz="0.007 -5.7144E-11 0.015147"
        rpy="0 0 0" />
      <mass
        value="0.067298" />
      <inertia
        ixx="0.0014386"
        ixy="9.8364E-05"
        ixz="3.0747E-13"
        iyy="1.5372E-05"
        iyz="-5.075E-13"
        izz="0.0014526" />
    </inertial>
    <visual>
      <origin
        xyz="0 0 0"
        rpy="0 0 0" />
      <geometry>
        <mesh
          filename="package://vtol_gauthali_11/meshes/rotor_3.STL" />
      </geometry>
      <material
        name="">
        <color
          rgba="1 1 1 1" />
      </material>
    </visual>
    <collision>
      <origin
        xyz="0 0 0"
        rpy="0 0 0" />
      <geometry>
        <mesh
          filename="package://vtol_gauthali_11/meshes/rotor_3.STL" />
      </geometry>
    </collision>
  </link>
  <joint
    name="rotor_3_joint"
    type="continuous">
    <origin
      xyz="-0.836 -0.35355 0.0064134"
      rpy="0 0 0" />
    <parent
      link="base_link" />
    <child
      link="rotor_3" />
    <axis
      xyz="0 0 1" />
  </joint>
  <link
    name="right_ruddervator">
    <inertial>
      <origin
        xyz="0.029088 -0.0084763 0.0071511"
        rpy="0 0 0" />
      <mass
        value="0.011825" />
      <inertia
        ixx="0.00022439"
        ixy="1.8506E-06"
        ixz="-3.6772E-10"
        iyy="5.7467E-06"
        iyz="-5.9487E-09"
        izz="0.00022971" />
    </inertial>
    <visual>
      <origin
        xyz="0 0 0"
        rpy="0 0 0" />
      <geometry>
        <mesh
          filename="package://vtol_gauthali_11/meshes/right_ruddervator.STL" />
      </geometry>
      <material
        name="">
        <color
          rgba="0.98824 0.73725 0.51765 1" />
      </material>
    </visual>
    <collision>
      <origin
        xyz="0 0 0"
        rpy="0 0 0" />
      <geometry>
        <mesh
          filename="package://vtol_gauthali_11/meshes/right_ruddervator.STL" />
      </geometry>
    </collision>
  </link>
  <joint
    name="right_ruddervator_joint"
    type="revolute">
    <origin
      xyz="-1.3278 -0.17783 0.17783"
      rpy="2.3562 0 3.1416" />
    <parent
      link="base_link" />
    <child
      link="right_ruddervator" />
    <axis
      xyz="0 1 0" />
    <limit
      lower="-0.53"
      upper="0.53"
      effort="-1"
      velocity="-1" />
  </joint>
  <link
    name="rotor_pusher">
    <inertial>
      <origin
        xyz="-0.0128 -4.7027E-08 -1.2312E-08"
        rpy="0 0 0" />
      <mass
        value="0.18697" />
      <inertia
        ixx="0.0045337"
        ixy="-3.9749E-11"
        ixz="-3.7147E-11"
        iyy="5.7998E-05"
        iyz="-0.00031475"
        izz="0.0044862" />
    </inertial>
    <visual>
      <origin
        xyz="0 0 0"
        rpy="0 0 0" />
      <geometry>
        <mesh
          filename="package://vtol_gauthali_10/meshes/rotor_pusher.STL" />
      </geometry>
      <material
        name="">
        <color
          rgba="0.79216 0.81961 0.93333 1" />
      </material>
    </visual>
    <collision>
      <origin
        xyz="0 0 0"
        rpy="0 0 0" />
      <geometry>
        <mesh
          filename="package://vtol_gauthali_11/meshes/rotor_pusher.STL" />
      </geometry>
    </collision>
  </link>
  <joint
    name="rotor_pusher_joint"
    type="continuous">
    <origin
      xyz="-0.50018 0 -0.058605"
      rpy="0 0 0" />
    <parent
      link="base_link" />
    <child
      link="rotor_pusher" />
    <axis
      xyz="1 0 0" />
  </joint>
</robot>
